# Item 9: Prefer try-with-resources to try-finally

使用 `try-finally` 可以確保資源可以正常被關閉，但如同 [Item 8](008.md) 所述，這樣的寫法會讓程式碼變得冗長且難以閱讀，而且較複雜的狀況可能會造成例外覆蓋難以除錯。

[//]: # (TODO: 例外覆蓋的範例)

Java 7 引入了 try-with-resources 來解決這個問題，這個語法可以讓程式碼更簡潔且易讀。類別需實作 `AutoCloseable` 介面，並實作 `close` 方法，這樣就可以在 try-with-resources 中使用。

## 使用 try-with-resources

```java
public class Main {
    public static class SimpleAutoCloseable implements AutoCloseable { // (1)!
        public void doIo(){
            System.err.println("SimpleAutoCloseable.doIo()");
        }

        @Override
        public void close() {
            System.err.println("SimpleAutoCloseable.close()");
        }
    }

    public static void main(String[] args) {
        try (SimpleAutoCloseable sac = new SimpleAutoCloseable()) { // (2)!
            sac.doIo();
        }
    }
}
```

1. `SimpleAutoCloseable` 實作 `AutoCloseable` 介面，並實作 `close` 方法。
2. 在 `try` 括號中宣告 `SimpleAutoCloseable` 物件，在 try 區塊結束時，無論有無發生例外，都會自動呼叫 `close` 方法。

程式的執行結果

```text
SimpleAutoCloseable.doIo()
SimpleAutoCloseable.close()
```

### try with multiple resources

```java
try (FileInputStream input = new FileInputStream(file1);
     FileOutputStream output = new FileOutputStream(file2)) {
}
```

### `try` 區塊發生例外: `close` 方法依然會被呼叫

```java hl_lines="5"
public class Main {
    public static class SimpleAutoCloseable implements AutoCloseable {
        public void doIo(){
            System.err.println("SimpleAutoCloseable.doIo()");
            throw new RuntimeException("Exception in doIo()");  // (1)!
        }

        @Override
        public void close() {
            System.err.println("SimpleAutoCloseable.close()");
        }
    }

    public static void main(String[] args) {
        try (SimpleAutoCloseable sac = new SimpleAutoCloseable()) {
            sac.doIo();
        }
    }
}
```

1. 故意在 `doIo` 方法中拋出例外，這會造成 `try` 區塊在呼叫時發生例外。

程式的執行結果:

```text
SimpleAutoCloseable.doIo()
SimpleAutoCloseable.close()
Exception in thread "main" java.lang.RuntimeException: Exception in doIo()
	at ...
```

如果要捕捉 `doIo` 方法的例外，可以在 `try` 增加 `catch` 區塊。

```java hl_lines="1 3-5"
try (...) {
    // ...
} catch (Exception e) {
    // handle exception
}
```
 
### `finally` 區塊發生例外

```java hl_lines="10"
public class Main {
    public static class SimpleAutoCloseable implements AutoCloseable {
        public void doIo(){
            System.err.println("SimpleAutoCloseable.doIo()");
        }

        @Override
        public void close() {
            System.err.println("SimpleAutoCloseable.close()");
            throw new RuntimeException("Exception in close()"); // (1)!
        }
    }

    public static void main(String[] args) {
        try (SimpleAutoCloseable sac = new SimpleAutoCloseable()) {
            sac.doIo();
        }
    }
}
```

1. 故意在 `close` 方法中拋出例外，會造成 `try` 區塊結束後執行的 `close` 方法發生例外。

執行結果:

```text
SimpleAutoCloseable.doIo()
SimpleAutoCloseable.close()
Exception in thread "main" java.lang.RuntimeException: Exception in close()
	at ... 
```

如果要捕捉 `doIo` 方法的例外，可以在 `try` 增加 `catch` 區塊。

```java hl_lines="1 3-5"
try (...) {
    // ...
} catch (Exception e) {
    // handle exception
}
```

### `try` 區塊與 `finally` 區塊都發生例外: `close` 方法的例外會被 Suppress

```java hl_lines="5 11"
public class Main {
    public static class SimpleAutoCloseable implements AutoCloseable {
        public void doIo() {
            System.err.println("SimpleAutoCloseable.doIo()");
            throw new RuntimeException("Exception in doIo()");  // (1)!
        }

        @Override
        public void close() {
            System.err.println("SimpleAutoCloseable.close()");
            throw new RuntimeException("Exception in close()");  // (2)!
        }
    }

    public static void main(String[] args) {
        try (SimpleAutoCloseable sac = new SimpleAutoCloseable()) {
            sac.doIo();
        }
    }
}
```

1. 故意在 `doIo` 方法中拋出例外，這會造成 `try` 區塊在呼叫時發生例外。
2. 故意在 `close` 方法中拋出例外，會造成 `try` 區塊結束後執行的 `close` 方法發生例外。

執行結果:

```text
SimpleAutoCloseable.doIo()
SimpleAutoCloseable.close()
Exception in thread "main" java.lang.RuntimeException: Exception in doIo()
	at ...
	Suppressed: java.lang.RuntimeException: Exception in close()
		at ...
```

!!! note "try-finally 的例外覆蓋行為"

    值得關注的是，try-with-resource 發生多個例外的行為，與 try-catch-finally 的多個例外行為不同。(Java 21)

    ```java
    try {
        throw new RuntimeException("Exception in try block");
    } finally {
        throw new RuntimeException("Exception in finally block");
    }
    ```

    執行結果
    
    ```text
    Exception in thread "main" java.lang.RuntimeException: Exception in finally block
        at ...
    ```

    這種情況，`try` 的例外訊息遺失了，這會造成**除錯上的困難**。而 try-with-resource 的例外行為，會將 `try` 的例外訊息保留下來，並將 `finally` 的例外訊息以 suppressed 的方式附加在後面。
